Workbook

Sheet Assumption
A2: MHP Model - Land (Major) vs POH (Minor)
A3: Structure | B3: Actual Units | C3: Lot Rent ($/mo) | D3: Home Rent ($/mo) | E3: Comments
A4: Lot Rent - Occupied | B4: 17 | C4: 275
A5: Lot Rent - Vacant | B5: 14
A6: RTO | B6: 20 | C6: 275 | D6: 370.6
A7: POH - Occupied | B7: 8 | C7: 275 | D7: 228.125
A8: POH - Vacant | B8: 9
A9: Office - Occupied | B9: 1 | D9: 500
A10: Office - Vacant
A11: Studio - Occupied
A12: Studio - Vacant
A13: SFR - Occupied
A14: SFR - Vacant
A15: SFH - Occupied
A16: SFH - Vacant
A17: RV - Occupied
A18: RV - Vacant
A19: Total | B19: =SUM(B4:B16) -> 69 | C19: =AVERAGE(C4:C12) -> 275

Sheet BOV 
A1: BOV Summary
A2: KEY PERFORMANCE INDICATORS | B2: Base case | C2: Worst case | D2: Best case
A3: Income
A4: Park Value | B4: 678462.15 | C4: =B4+$B$39 -> 728462.15 | D4: =B4-$B$39 -> 628462.15 | F4: Maximum price
A5: 10000 | B5: =A5*(Assumption!B7+Assumption!B8+Assumption!B6) -> 370000 | C5: =$B$5 -> 370000 | D5: =$B$5 -> 370000
A6: Total Value | B6: =B4+B5 -> 1048462.1 | C6: =C4+C5 -> 1098462.1 | D6: =D4+D5 -> 998462.15
A7: Investment Performance
A8: Unlevered IRR | B8: ='Cash Flow Model'!B43 -> 0.095531206 | C8: =IRR(_xlfn.HSTACK(-(B6+200000),'Cash Flow Model'!C40:L40)) -> 0.065711364 | D8: =IRR(_xlfn.HSTACK(-(B6-200000),'Cash Flow Model'!C40:L40)) -> 0.13519327
A9: Cash-on-Cash (Year 1) | B9: ='Cash Flow Model'!$C$24/B27 -> 0.19648914 | C9: ='Cash Flow Model'!$C$24/C27 -> 0.18754531 | D9: ='Cash Flow Model'!$C$24/D27 -> 0.20632873
A10: Cash-on-Cash (Avg.) | B10: ='Cash Flow Model'!B46 -> 0.15499559 | C10: =(SUMPRODUCT(('Cash Flow Model'!$C$38:$L$38<=$B$38)*'Cash Flow Model'!$C$19:$L$19)-C25)/$B$38/C27 -> 0.22714599 | D10: =(SUMPRODUCT(('Cash Flow Model'!$C$38:$L$38<=$B$38)*'Cash Flow Model'!$C$19:$L$19)-D25)/$B$38/D27 -> 0.2684827
A11: DSCR (Year 1) | B11: =B26/B23 -> 1.251279 | C11: =C26/C23 -> 1.194323 | D11: =D26/D23 -> 1.3139393
A12: DSCR Test (vs. requirement) | B12: =IF(B11>=$B$31-0.00001,"PASS","FAIL") -> PASS | C12: =IF(C11>=$B$31-0.00001,"PASS","FAIL") -> FAIL | D12: =IF(D11>=$B$31-0.00001,"PASS","FAIL") -> PASS
A13: Equity Multiple | B13: ='Cash Flow Model'!B44 -> 2.2964913 | C13: =(SUM('Cash Flow Model'!$C$39:$L$39)-(C25-$B$25)-(C28-$B$28))/C27 -> 1.8571337 | D13: =(SUM('Cash Flow Model'!$C$39:$L$39)-(D25-$B$25)-(D28-$B$28))/D27 -> 2.3552358
A14: Valuation Ratios (move with price)
A15: Going-in Cap Rate (NOI Year 1 / Price) | B15: =B26/B6 -> 0.069665724 | C15: =C26/C6 -> 0.066494667 | D15: =D26/D6 -> 0.073154376
A16: Debt Yield (NOI Year 1 / Loan) | B16: =B26/B20 -> 0.099522463 | C16: =C26/C20 -> 0.094992382 | D16: =D26/D20 -> 0.10450625
A17: Price per Unit | B17: =B6/Land!$P$29 -> 15195.104 | C17: =C6/Land!$P$29 -> 15919.741 | D17: =D6/Land!$P$29 -> 14470.466
A18: Debt
A19: LTV | B19: 0.7 | C19: =$B$19 -> 0.7 | D19: =$B$19 -> 0.7
A20: Loan Amount | B20: =B19*B6 -> 733923.5 | C20: =C19*C6 -> 768923.5 | D20: =D19*D6 -> 698923.5
A21: Interest Rate | B21: =$B$34 -> 0.0687 | C21: =$B$34 -> 0.0687 | D21: =$B$34 -> 0.0687
A22: Interest Amount (Year 1) | B22: =B20*B21 -> 50420.545 | C22: =C20*C21 -> 52825.045 | D22: =D20*D21 -> 48016.045
A23: Debt Service (Year 1) | B23: =IF($B$36>=1,B22,B24) -> 58373.774 | C23: =IF($B$36>=1,C22,C24) -> 61157.554 | D23: =IF($B$36>=1,D22,D24) -> 55589.993
A24: Debt Service after IO Period | B24: =-PMT(B21,$B$35,B20) -> 58373.774 | C24: =-PMT(C21,$B$35,C20) -> 61157.554 | D24: =-PMT(D21,$B$35,D20) -> 55589.993
A25: Total Debt Service over Hold | B25: =MIN($B$36,$B$38)*B22+MAX($B$38-$B$36,0)*B24 -> 291868.87 | C25: =MIN($B$36,$B$38)*C22+MAX($B$38-$B$36,0)*C24 -> 305787.77 | D25: =MIN($B$36,$B$38)*D22+MAX($B$38-$B$36,0)*D24 -> 277949.96
A26: NOI | B26: =Land!C61 -> 73041.875 | C26: =$B$26 -> 73041.875 | D26: =$B$26 -> 73041.875
A27: Equity Invested | B27: =B6-B20 -> 314538.64 | C27: =C6-C20 -> 329538.64 | D27: =D6-D20 -> 299538.64
A28: Loan Balance at Sale | B28: ='Cash Flow Model'!B33 -> 624710.55 | C28: =IF($B$36>=$B$38,C20,C20*(1+C21)^($B$38-$B$36)-C24*((1+C21)^($B$38-$B$36)-1)/C21) -> 721129.56 | D28: =IF($B$36>=$B$38,D20,D20*(1+D21)^($B$38-$B$36)-D24*((1+D21)^($B$38-$B$36)-1)/D21) -> 655480.54
A30: OTHER INPUTS
A31: DSCR Requirement | B31: 1.25
A32: SOFR | B32: 0.0387
A33: Spread | B33: 0.03
A34: Interest Rate (SOFR + Spread) | B34: =B32+B33 -> 0.0687
A35: Amortization (Years) | B35: 30
A36: Interest-Only Period | B36: 0
A37: POH Cap Rate | B37: 0.1
A38: Hold Period | B38: 5
A39: Price Step for Worst / Best Cases | B39: 50000

Sheet Land
A1: Land - Lots Only
A2: Head / Category | C2: Actual | D2: Year 1 | E2: Year 2 | F2: Year 3 | G2: Year 4 | H2: Year 5 | I2: Year 6 | J2: Year 7 | K2: Year 8 | L2: Year 9 | M2: Year 10 | O2: Base Year Vacant | P2: Total Units | Q2: Lease-Up / Yr
A4: Occupied Lots | C4: =Assumption!B4+Assumption!B7+Assumption!B6 -> 45 | D4: =MIN(C4+$Q4,$P$4*90%) -> 47 | E4: =MIN(D4+$Q4,$P$4*90%) -> 49 | F4: =MIN(E4+$Q4,$P$4*90%) -> 51 | G4: =MIN(F4+$Q4,$P$4*90%) -> 53 | H4: =MIN(G4+$Q4,$P$4*90%) -> 55 | I4: =MIN(H4+$Q4,$P$4*90%) -> 57 | J4: =MIN(I4+$Q4,$P$4*90%) -> 59 | K4: =MIN(J4+$Q4,$P$4*90%) -> 61 | ... M4: =MIN(L4+$Q4,$P$4*90%) -> 61.2 | O4: =P4-C4 -> 23 | P4: =SUM(Assumption!B4:B8) -> 68 | Q4: 2
A5: Occupancy | C5: =C4/SUM(Assumption!$B$4:$B$8) -> 0.66176471 | D5: =D4/SUM(Assumption!$B$4:$B$8) -> 0.69117647 | E5: =E4/SUM(Assumption!$B$4:$B$8) -> 0.72058824 | F5: =F4/SUM(Assumption!$B$4:$B$8) -> 0.75 | G5: =G4/SUM(Assumption!$B$4:$B$8) -> 0.77941176 | H5: =H4/SUM(Assumption!$B$4:$B$8) -> 0.80882353 | I5: =I4/SUM(Assumption!$B$4:$B$8) -> 0.83823529 | J5: =J4/SUM(Assumption!$B$4:$B$8) -> 0.86764706 | ... M5: =M4/SUM(Assumption!$B$4:$B$8) -> 0.9
A6: Average Rent | C6: =AVERAGE(Assumption!C4,Assumption!C6,Assumption!C7) -> 275 | D6: =C6*(1+$P$32) -> 283.25 | E6: =D6*(1+$P$32) -> 291.7475 | F6: =E6*(1+$P$32) -> 300.49993 | G6: =F6*(1+$P$32) -> 309.51492 | H6: =G6*(1+$P$32) -> 318.80037 | I6: =H6*(1+$P$32) -> 328.36438 | J6: =I6*(1+$P$32) -> 338.21531 | K6: =J6*(1+$P$32) -> 348.36177 | ... M6: =L6*(1+$P$32) -> 369.577
A7: Rent Increase (%) | D7: =(D6-C6)/D6 -> 0.029126214 | E7: =(E6-D6)/E6 -> 0.029126214 | F7: =(F6-E6)/F6 -> 0.029126214 | G7: =(G6-F6)/G6 -> 0.029126214 | H7: =(H6-G6)/H6 -> 0.029126214 | I7: =(I6-H6)/I6 -> 0.029126214 | J7: =(J6-I6)/J6 -> 0.029126214 | K7: =(K6-J6)/K6 -> 0.029126214 | ... M7: =(M6-L6)/M6 -> 0.029126214
A9: Occupied Office | C9: =Assumption!B9 -> 1 | D9: =MIN($P9,C9+$Q9) -> 1 | E9: =MIN($P9,D9+$Q9) -> 1 | F9: =MIN($P9,E9+$Q9) -> 1 | G9: =MIN($P9,F9+$Q9) -> 1 | H9: =MIN($P9,G9+$Q9) -> 1 | I9: =MIN($P9,H9+$Q9) -> 1 | J9: =MIN($P9,I9+$Q9) -> 1 | K9: =MIN($P9,J9+$Q9) -> 1 | ... M9: =MIN($P9,L9+$Q9) -> 1 | O9: =P9-C9 -> 0 | P9: =Assumption!B9+Assumption!B10 -> 1 | Q9: 1
A10: Occupancy | C10: =C9/SUM(Assumption!$B$9:$B$10) -> 1 | D10: =D9/SUM(Assumption!$B$9:$B$10) -> 1 | E10: =E9/SUM(Assumption!$B$9:$B$10) -> 1 | F10: =F9/SUM(Assumption!$B$9:$B$10) -> 1 | G10: =G9/SUM(Assumption!$B$9:$B$10) -> 1 | H10: =H9/SUM(Assumption!$B$9:$B$10) -> 1 | I10: =I9/SUM(Assumption!$B$9:$B$10) -> 1 | J10: =J9/SUM(Assumption!$B$9:$B$10) -> 1 | ... M10: =M9/SUM(Assumption!$B$9:$B$10) -> 1
A11: Average Rent | C11: =Assumption!D9 -> 500 | D11: =C11*(1+$P$33) -> 515 | E11: =D11*(1+$P$33) -> 530.45 | F11: =E11*(1+$P$33) -> 546.3635 | G11: =F11*(1+$P$33) -> 562.75441 | H11: =G11*(1+$P$33) -> 579.63704 | I11: =H11*(1+$P$33) -> 597.02615 | J11: =I11*(1+$P$33) -> 614.93693 | K11: =J11*(1+$P$33) -> 633.38504 | ... M11: =L11*(1+$P$33) -> 671.95819
A12: Rent Increase (%) | D12: =(D11-C11)/D11 -> 0.029126214 | E12: =(E11-D11)/E11 -> 0.029126214 | F12: =(F11-E11)/F11 -> 0.029126214 | G12: =(G11-F11)/G11 -> 0.029126214 | H12: =(H11-G11)/H11 -> 0.029126214 | I12: =(I11-H11)/I11 -> 0.029126214 | J12: =(J11-I11)/J11 -> 0.029126214 | K12: =(K11-J11)/K11 -> 0.029126214 | ... M12: =(M11-L11)/M11 -> 0.029126214
A14: Occupied Studio | C14: =Assumption!B11 -> 0 | D14: =MIN($P14,C14+$Q14) -> 0 | E14: =MIN($P14,D14+$Q14) -> 0 | F14: =MIN($P14,E14+$Q14) -> 0 | G14: =MIN($P14,F14+$Q14) -> 0 | H14: =MIN($P14,G14+$Q14) -> 0 | I14: =MIN($P14,H14+$Q14) -> 0 | J14: =MIN($P14,I14+$Q14) -> 0 | K14: =MIN($P14,J14+$Q14) -> 0 | ... M14: =MIN($P14,L14+$Q14) -> 0 | O14: =P14-C14 -> 0 | P14: =Assumption!B11+Assumption!B12 -> 0 | Q14: 1
A15: Occupancy | C15: =C14/SUM(Assumption!B11:$B$12) -> #DIV/0! | D15: =D14/SUM(Assumption!$B$11:$C$12) -> #DIV/0! | E15: =E14/SUM(Assumption!$B$11:$C$12) -> #DIV/0! | F15: =F14/SUM(Assumption!$B$11:$C$12) -> #DIV/0! | G15: =G14/SUM(Assumption!$B$11:$C$12) -> #DIV/0! | H15: =H14/SUM(Assumption!$B$11:$C$12) -> #DIV/0! | I15: =I14/SUM(Assumption!$B$11:$C$12) -> #DIV/0! | J15: =J14/SUM(Assumption!$B$11:$C$12) -> #DIV/0! | K15: =K14/SUM(Assumption!$B$11:$C$12) -> #DIV/0! | ... M15: =M14/SUM(Assumption!$B$11:$C$12) -> #DIV/0!
A16: Average Rent | C16: =Assumption!D11 -> 0 | D16: =C16*(1+$P$34) -> 0 | E16: =D16*(1+$P$34) -> 0 | F16: =E16*(1+$P$34) -> 0 | G16: =F16*(1+$P$34) -> 0 | H16: =G16*(1+$P$34) -> 0 | I16: =H16*(1+$P$34) -> 0 | J16: =I16*(1+$P$34) -> 0 | K16: =J16*(1+$P$34) -> 0 | ... M16: =L16*(1+$P$34) -> 0
A17: Rent Increase (%) | D17: =(D16-C16)/D16 -> #DIV/0! | E17: =(E16-D16)/E16 -> #DIV/0! | F17: =(F16-E16)/F16 -> #DIV/0! | G17: =(G16-F16)/G16 -> #DIV/0! | H17: =(H16-G16)/H16 -> #DIV/0! | I17: =(I16-H16)/I16 -> #DIV/0! | J17: =(J16-I16)/J16 -> #DIV/0! | K17: =(K16-J16)/K16 -> #DIV/0! | ... M17: =(M16-L16)/M16 -> #DIV/0!
A19: Occupied SFR | C19: =Assumption!B13 -> 0 | D19: =MIN($P19,C19+$Q19) -> 0 | E19: =MIN($P19,D19+$Q19) -> 0 | F19: =MIN($P19,E19+$Q19) -> 0 | G19: =MIN($P19,F19+$Q19) -> 0 | H19: =MIN($P19,G19+$Q19) -> 0 | I19: =MIN($P19,H19+$Q19) -> 0 | J19: =MIN($P19,I19+$Q19) -> 0 | K19: =MIN($P19,J19+$Q19) -> 0 | ... M19: =MIN($P19,L19+$Q19) -> 0 | O19: =P19-C19 -> 0 | P19: =Assumption!B13+Assumption!B14 -> 0 | Q19: 1
A20: Occupancy | C20: =C19/SUM(Assumption!$B$13:$B$14) -> #DIV/0! | D20: =D19/SUM(Assumption!$B$13:$B$14) -> #DIV/0! | E20: =E19/SUM(Assumption!$B$13:$B$14) -> #DIV/0! | F20: =F19/SUM(Assumption!$B$13:$B$14) -> #DIV/0! | G20: =G19/SUM(Assumption!$B$13:$B$14) -> #DIV/0! | H20: =H19/SUM(Assumption!$B$13:$B$14) -> #DIV/0! | I20: =I19/SUM(Assumption!$B$13:$B$14) -> #DIV/0! | J20: =J19/SUM(Assumption!$B$13:$B$14) -> #DIV/0! | ... M20: =M19/SUM(Assumption!$B$13:$B$14) -> #DIV/0!
A21: Average Rent | C21: =Assumption!D13 -> 0 | D21: =C21*(1+$P$35) -> 0 | E21: =D21*(1+$P$35) -> 0 | F21: =E21*(1+$P$35) -> 0 | G21: =F21*(1+$P$35) -> 0 | H21: =G21*(1+$P$35) -> 0 | I21: =H21*(1+$P$35) -> 0 | J21: =I21*(1+$P$35) -> 0 | K21: =J21*(1+$P$35) -> 0 | ... M21: =L21*(1+$P$35) -> 0
A22: Rent Increase (%) | D22: =(D21-C21)/D21 -> #DIV/0! | E22: =(E21-D21)/E21 -> #DIV/0! | F22: =(F21-E21)/F21 -> #DIV/0! | G22: =(G21-F21)/G21 -> #DIV/0! | H22: =(H21-G21)/H21 -> #DIV/0! | I22: =(I21-H21)/I21 -> #DIV/0! | J22: =(J21-I21)/J21 -> #DIV/0! | K22: =(K21-J21)/K21 -> #DIV/0! | ... M22: =(M21-L21)/M21 -> #DIV/0!
A24: Occupied SFH | C24: =Assumption!B15 -> 0 | D24: =MIN($P24,C24+$Q24) -> 0 | E24: =MIN($P24,D24+$Q24) -> 0 | F24: =MIN($P24,E24+$Q24) -> 0 | G24: =MIN($P24,F24+$Q24) -> 0 | H24: =MIN($P24,G24+$Q24) -> 0 | I24: =MIN($P24,H24+$Q24) -> 0 | J24: =MIN($P24,I24+$Q24) -> 0 | K24: =MIN($P24,J24+$Q24) -> 0 | ... M24: =MIN($P24,L24+$Q24) -> 0 | O24: =P24-C24 -> 0 | P24: =Assumption!B15+Assumption!B16 -> 0 | Q24: 1
A25: Occupancy | C25: =C24/SUM(Assumption!$B$15:$B$16) -> #DIV/0! | D25: =D24/SUM(Assumption!$B$15:$B$16) -> #DIV/0! | E25: =E24/SUM(Assumption!$B$15:$B$16) -> #DIV/0! | F25: =F24/SUM(Assumption!$B$15:$B$16) -> #DIV/0! | G25: =G24/SUM(Assumption!$B$15:$B$16) -> #DIV/0! | H25: =H24/SUM(Assumption!$B$15:$B$16) -> #DIV/0! | I25: =I24/SUM(Assumption!$B$15:$B$16) -> #DIV/0! | J25: =J24/SUM(Assumption!$B$15:$B$16) -> #DIV/0! | ... M25: =M24/SUM(Assumption!$B$15:$B$16) -> #DIV/0!
A26: Average Rent | C26: =Assumption!D15 -> 0 | D26: =C26*(1+$P$36) -> 0 | E26: =D26*(1+$P$36) -> 0 | F26: =E26*(1+$P$36) -> 0 | G26: =F26*(1+$P$36) -> 0 | H26: =G26*(1+$P$36) -> 0 | I26: =H26*(1+$P$36) -> 0 | J26: =I26*(1+$P$36) -> 0 | K26: =J26*(1+$P$36) -> 0 | ... M26: =L26*(1+$P$36) -> 0
A27: Rent Increase (%) | D27: =(D26-C26)/D26 -> #DIV/0! | E27: =(E26-D26)/E26 -> #DIV/0! | F27: =(F26-E26)/F26 -> #DIV/0! | G27: =(G26-F26)/G26 -> #DIV/0! | H27: =(H26-G26)/H26 -> #DIV/0! | I27: =(I26-H26)/I26 -> #DIV/0! | J27: =(J26-I26)/J26 -> #DIV/0! | K27: =(K26-J26)/K26 -> #DIV/0! | ... M27: =(M26-L26)/M26 -> #DIV/0!
A29: Total Occupied Units | C29: =C4+C9+C14+C19+C24 -> 46 | D29: =D4+D9+D14+D19+D24 -> 48 | E29: =E4+E9+E14+E19+E24 -> 50 | F29: =F4+F9+F14+F19+F24 -> 52 | G29: =G4+G9+G14+G19+G24 -> 54 | H29: =H4+H9+H14+H19+H24 -> 56 | I29: =I4+I9+I14+I19+I24 -> 58 | J29: =J4+J9+J14+J19+J24 -> 60 | ... M29: =M4+M9+M14+M19+M24 -> 62.2 | O29: =SUM(O4:O24) -> 23 | P29: =SUM(P4:P24) -> 69
A31: Revenue Head | B31: Actual | C31: Pro Forma | D31: Year 1 | E31: Year 2 | F31: Year 3 | G31: Year 4 | H31: Year 5 | I31: Year 6 | J31: Year 7 | K31: Year 8 | L31: Year 9 | M31: Year 10 | O31: Description | P31: Growth
A32: Lot Rent | B32: 148500 | C32: =C4*C6*12 -> 148500 | D32: =D4*D6*12 -> 159753 | E32: =E4*E6*12 -> 171547.53 | F32: =F4*F6*12 -> 183905.95 | G32: =G4*G6*12 -> 196851.49 | H32: =H4*H6*12 -> 210408.24 | I32: =I4*I6*12 -> 224601.24 | J32: =J4*J6*12 -> 239456.44 | ... M32: =M4*M6*12 -> 271417.35 | O32: =A32&"Increased by "&TEXT(P32,"0%")&" annually" -> Lot Rent Increased by 3% annually | P32: 0.03
A33: Office Rent | C33: =C9*C11 -> 500 | D33: =D9*D11 -> 515 | E33: =E9*E11 -> 530.45 | F33: =F9*F11 -> 546.3635 | G33: =G9*G11 -> 562.75441 | H33: =H9*H11 -> 579.63704 | I33: =I9*I11 -> 597.02615 | J33: =J9*J11 -> 614.93693 | ... M33: =M9*M11 -> 671.95819 | O33: =A33&"Increased by "&TEXT(P33,"0%")&" annually" -> Office Rent Increased by 3% annually | P33: 0.03
A34: Studio Rent | B34: 0 | C34: =B34 -> 0 | D34: =D14*D16 -> 0 | E34: =E14*E16 -> 0 | F34: =F14*F16 -> 0 | G34: =G14*G16 -> 0 | H34: =H14*H16 -> 0 | I34: =I14*I16 -> 0 | J34: =J14*J16 -> 0 | K34: =K14*K16 -> 0 | ... M34: =M14*M16 -> 0 | O34: =A34&"Increased by "&TEXT(P34,"0%")&" annually" -> Studio Rent Increased by 5% annually | P34: 0.05
A35: SFR Rent | B35: 0 | C35: =B35 -> 0 | D35: =D19*D21 -> 0 | E35: =E19*E21 -> 0 | F35: =F19*F21 -> 0 | G35: =G19*G21 -> 0 | H35: =H19*H21 -> 0 | I35: =I19*I21 -> 0 | J35: =J19*J21 -> 0 | K35: =K19*K21 -> 0 | ... M35: =M19*M21 -> 0 | O35: =A35&"Increased by "&TEXT(P35,"0%")&" annually" -> SFR Rent Increased by 5% annually | P35: 0.05
A36: SFH Rent | B36: 0 | C36: =B36 -> 0 | D36: =D24*D26 -> 0 | E36: =E24*E26 -> 0 | F36: =F24*F26 -> 0 | G36: =G24*G26 -> 0 | H36: =H24*H26 -> 0 | I36: =I24*I26 -> 0 | J36: =J24*J26 -> 0 | K36: =K24*K26 -> 0 | ... M36: =M24*M26 -> 0 | O36: =A36&"Increased by "&TEXT(P36,"0%")&" annually" -> SFH Rent Increased by 5% annually | P36: 0.05
A37: Less: Vacancy Loss | C37: =(((C4-$P$4)*C6)+((C9-$P$9)*C11))+((C14-$P$14)*C16)+((C19-$P$19)*C21)+((C24-$P$24)*C26) -> -6325 | D37: =(((D4-$P$4)*D6)+((D9-$P$9)*D11))+((D14-$P$14)*D16)+((D19-$P$19)*D21)+((D24-$P$24)*D26) -> -5948.25 | E37: =(((E4-$P$4)*E6)+((E9-$P$9)*E11))+((E14-$P$14)*E16)+((E19-$P$19)*E21)+((E24-$P$24)*E26) -> -5543.2025 | F37: =(((F4-$P$4)*F6)+((F9-$P$9)*F11))+((F14-$P$14)*F16)+((F19-$P$19)*F21)+((F24-$P$24)*F26) -> -5108.4987 | G37: =(((G4-$P$4)*G6)+((G9-$P$9)*G11))+((G14-$P$14)*G16)+((G19-$P$19)*G21)+((G24-$P$24)*G26) -> -4642.7238 | H37: =(((H4-$P$4)*H6)+((H9-$P$9)*H11))+((H14-$P$14)*H16)+((H19-$P$19)*H21)+((H24-$P$24)*H26) -> -4144.4048 | I37: =(((I4-$P$4)*I6)+((I9-$P$9)*I11))+((I14-$P$14)*I16)+((I19-$P$19)*I21)+((I24-$P$24)*I26) -> -3612.0082 | J37: =(((J4-$P$4)*J6)+((J9-$P$9)*J11))+((J14-$P$14)*J16)+((J19-$P$19)*J21)+((J24-$P$24)*J26) -> -3043.9378 | ... M37: =(((M4-$P$4)*M6)+((M9-$P$9)*M11))+((M14-$P$14)*M16)+((M19-$P$19)*M21)+((M24-$P$24)*M26) -> -2513.1236
A38: Less: Non-Cash Rent | B38: 0 | C38: =B38 -> 0 | D38: 0 | E38: 0 | F38: 0 | G38: 0 | H38: 0 | I38: 0 | J38: 0 | K38: 0 | L38: 0 | M38: 0
A39: Less: Concessions | B39: 0 | C39: =B39 -> 0 | D39: 0 | E39: 0 | F39: 0 | G39: 0 | H39: 0 | I39: 0 | J39: 0 | K39: 0 | L39: 0 | M39: 0
A40: Utility Recapture | B40: 13655 | C40: =B40 -> 13655 | D40: =D50*$P$40 -> 14961.13 | E40: =E50*$P$40 -> 15584.511 | F40: =F50*$P$40 -> 16207.891 | G40: =G50*$P$40 -> 16831.272 | H40: =H50*$P$40 -> 17454.652 | I40: =I50*$P$40 -> 18078.033 | J40: =J50*$P$40 -> 18701.413 | K40: =K50*$P$40 -> 19324.793 | ... M40: =M50*$P$40 -> 19387.132 | O40: Recapture Rate | P40: =C40/B50 -> 0.9756359
A41: Less: Bad Debt | C41: =-$P$41*(SUM(C32:C36)+C37+C38+C39) -> -2853.5 | D41: =-$P$41*(SUM(D32:D36)+D37+D38+D39) -> -3086.395 | E41: =-$P$41*(SUM(E32:E36)+E37+E38+E39) -> -3330.6955 | F41: =-$P$41*(SUM(F32:F36)+F37+F38+F39) -> -3586.8764 | G41: =-$P$41*(SUM(G32:G36)+G37+G38+G39) -> -3855.4304 | H41: =-$P$41*(SUM(H32:H36)+H37+H38+H39) -> -4136.8695 | I41: =-$P$41*(SUM(I32:I36)+I37+I38+I39) -> -4431.7251 | J41: =-$P$41*(SUM(J32:J36)+J37+J38+J39) -> -4740.5488 | ... M41: =-$P$41*(SUM(M32:M36)+M37+M38+M39) -> -5391.5237 | O41: ="Assumed "&TEXT(P41,"0%") -> Assumed 2% | P41: 0.02
A42: Total Revenue | B42: =SUM(B32:B41) -> 162155 | C42: =SUM(C32:C41) -> 153476.5 | D42: =SUM(D32:D41) -> 166194.49 | E42: =SUM(E32:E41) -> 178788.59 | F42: =SUM(F32:F41) -> 191964.83 | G42: =SUM(G32:G41) -> 205747.36 | H42: =SUM(H32:H41) -> 220161.26 | I42: =SUM(I32:I41) -> 235232.56 | ... M42: =SUM(M32:M41) -> 283571.79
A44: Expense Head | B44: Actual | C44: Pro Forma | D44: Year 1 | E44: Year 2 | F44: Year 3 | G44: Year 4 | H44: Year 5 | I44: Year 6 | J44: Year 7 | K44: Year 8 | L44: Year 9 | M44: Year 10 | O44: Description | P44: Growth | R44: Rate B / Count | S44: Est. Base Year
A45: Property Tax | B45: 4764 | C45: ='Property Tax Working '!G10 -> 10810.8 | D45: =C45*(1+$P45) -> 11351.34 | E45: =D45*(1+$P45) -> 11918.907 | F45: =E45*(1+$P45) -> 12514.852 | G45: =F45*(1+$P45) -> 13140.595 | H45: =G45*(1+$P45) -> 13797.625 | I45: =H45*(1+$P45) -> 14487.506 | J45: =I45*(1+$P45) -> 15211.881 | K45: =J45*(1+$P45) -> 15972.475 | ... M45: =L45*(1+$P45) -> 17609.654 | O45: Expensed as per tax bill | P45: 0.05
A46: Insurance | B46: 4619 | C46: =B46 -> 4619 | D46: =C46*(1+$P46) -> 4757.57 | E46: =D46*(1+$P46) -> 4900.2971 | F46: =E46*(1+$P46) -> 5047.306 | G46: =F46*(1+$P46) -> 5198.7252 | H46: =G46*(1+$P46) -> 5354.6869 | I46: =H46*(1+$P46) -> 5515.3276 | J46: =I46*(1+$P46) -> 5680.7874 | K46: =J46*(1+$P46) -> 5851.211 | ... M46: =L46*(1+$P46) -> 6207.5498 | O46: =IF(AND(B46=0,C46=0),"",IF(B46=C46,"Pro Forma Increased "&TEXT($P46,"0%")&" annually","Assumed "&TEXT(Q46,"0%"))) -> Pro Forma Increased 3% annually | P46: 0.03 | Q46: 0.02
A47: Advertising | B47: 780 | C47: =B47 -> 780 | D47: =C47*(1+$P47) -> 803.4 | E47: =D47*(1+$P47) -> 827.502 | F47: =E47*(1+$P47) -> 852.32706 | G47: =F47*(1+$P47) -> 877.89687 | H47: =G47*(1+$P47) -> 904.23378 | I47: =H47*(1+$P47) -> 931.36079 | J47: =I47*(1+$P47) -> 959.30162 | K47: =J47*(1+$P47) -> 988.08066 | ... M47: =L47*(1+$P47) -> 1048.2548 | O47: =IF(AND(B47=0,C47=0),"",IF(B47=C47,"Pro Forma Increased "&TEXT($P47,"0%")&" annually","")) -> Pro Forma Increased 3% annually | P47: 0.03
A48: Utilities | B48: 0 | C48: =B48 -> 0 | D48: =C48*(1+$P48) -> 0 | E48: =D48*(1+$P48) -> 0 | F48: =E48*(1+$P48) -> 0 | G48: =F48*(1+$P48) -> 0 | H48: =G48*(1+$P48) -> 0 | I48: =H48*(1+$P48) -> 0 | J48: =I48*(1+$P48) -> 0 | K48: =J48*(1+$P48) -> 0 | ... M48: =L48*(1+$P48) -> 0 | O48: =IF(AND(B48=0,C48=0),"",IF(B48=C48,"Pro Forma Increased by "&TEXT($P48,"0%")&" annually","")) | P48: 0.03
...

Sheet POH 
A1: Park Owned Homes
A2: Head / Category | C2: Actual | D2: Year 1 | E2: Year 2 | F2: Year 3 | G2: Year 4 | H2: Year 5 | I2: Year 6 | J2: Year 7 | K2: Year 8 | L2: Year 9 | M2: Year 10 | O2: Base Year Vacant | P2: Total Units | Q2: Lease-Up / Yr
A4: Occupied POH | C4: =Assumption!B7 -> 8 | D4: =MIN(C4+$Q4,$P$4*95%) -> 8.8 | E4: =MIN(D4+$Q4,$P$4*95%) -> 9.6 | F4: =MIN(E4+$Q4,$P$4*95%) -> 10.4 | G4: =MIN(F4+$Q4,$P$4*95%) -> 11.2 | H4: =MIN(G4+$Q4,$P$4*95%) -> 12 | I4: =MIN(H4+$Q4,$P$4*95%) -> 12.8 | J4: =MIN(I4+$Q4,$P$4*95%) -> 13.6 | K4: =MIN(J4+$Q4,$P$4*95%) -> 14.4 | ... M4: =MIN(L4+$Q4,$P$4*95%) -> 16 | O4: =P4-C4 -> 9 | P4: =SUM(Assumption!B7:B8) -> 17 | Q4: 0.8
A5: Occupancy | C5: =C4/SUM(Assumption!$B$7:$B$8) -> 0.47058824 | D5: =D4/SUM(Assumption!$B$7:$B$8) -> 0.51764706 | E5: =E4/SUM(Assumption!$B$7:$B$8) -> 0.56470588 | F5: =F4/SUM(Assumption!$B$7:$B$8) -> 0.61176471 | G5: =G4/SUM(Assumption!$B$7:$B$8) -> 0.65882353 | H5: =H4/SUM(Assumption!$B$7:$B$8) -> 0.70588235 | I5: =I4/SUM(Assumption!$B$7:$B$8) -> 0.75294118 | J5: =J4/SUM(Assumption!$B$7:$B$8) -> 0.8 | ... M5: =M4/SUM(Assumption!$B$7:$B$8) -> 0.94117647
A6: Average POH Rent | C6: =Assumption!D7 -> 228.125 | D6: =C6*(1+$P$17) -> 232.6875 | E6: =D6*(1+$P$17) -> 237.34125 | F6: =E6*(1+$P$17) -> 242.08808 | G6: =F6*(1+$P$17) -> 246.92984 | H6: =G6*(1+$P$17) -> 251.86843 | I6: =H6*(1+$P$17) -> 256.9058 | J6: =I6*(1+$P$17) -> 262.04392 | K6: =J6*(1+$P$17) -> 267.2848 | ... M6: =L6*(1+$P$17) -> 278.0831
A7: Rent Increase (%) | D7: =(D6-C6)/D6 -> 0.019607843 | E7: =(E6-D6)/E6 -> 0.019607843 | F7: =(F6-E6)/F6 -> 0.019607843 | G7: =(G6-F6)/G6 -> 0.019607843 | H7: =(H6-G6)/H6 -> 0.019607843 | I7: =(I6-H6)/I6 -> 0.019607843 | J7: =(J6-I6)/J6 -> 0.019607843 | K7: =(K6-J6)/K6 -> 0.019607843 | ... M7: =(M6-L6)/M6 -> 0.019607843
A9: Occupied RV | C9: =Assumption!B17 -> 0 | D9: =MIN($P9,C9+$Q9) -> 0 | E9: =MIN($P9,D9+$Q9) -> 0 | F9: =MIN($P9,E9+$Q9) -> 0 | G9: =MIN($P9,F9+$Q9) -> 0 | H9: =MIN($P9,G9+$Q9) -> 0 | I9: =MIN($P9,H9+$Q9) -> 0 | J9: =MIN($P9,I9+$Q9) -> 0 | K9: =MIN($P9,J9+$Q9) -> 0 | ... M9: =MIN($P9,L9+$Q9) -> 0 | O9: =P9-C9 -> 0 | P9: =Assumption!B17+Assumption!B18 -> 0 | Q9: 0
A10: Occupancy | C10: =C9/SUM(Assumption!$B$17:$B$18) -> #DIV/0! | D10: =D9/SUM(Assumption!$B$17:$B$18) -> #DIV/0! | E10: =E9/SUM(Assumption!$B$17:$B$18) -> #DIV/0! | F10: =F9/SUM(Assumption!$B$17:$B$18) -> #DIV/0! | G10: =G9/SUM(Assumption!$B$17:$B$18) -> #DIV/0! | H10: =H9/SUM(Assumption!$B$17:$B$18) -> #DIV/0! | I10: =I9/SUM(Assumption!$B$17:$B$18) -> #DIV/0! | J10: =J9/SUM(Assumption!$B$17:$B$18) -> #DIV/0! | ... M10: =M9/SUM(Assumption!$B$17:$B$18) -> #DIV/0!
A11: Average RV Rent | C11: =Assumption!D17 -> 0 | D11: =C11*(1+$P$18) -> 0 | E11: =D11*(1+$P$18) -> 0 | F11: =E11*(1+$P$18) -> 0 | G11: =F11*(1+$P$18) -> 0 | H11: =G11*(1+$P$18) -> 0 | I11: =H11*(1+$P$18) -> 0 | J11: =I11*(1+$P$18) -> 0 | K11: =J11*(1+$P$18) -> 0 | ... M11: =L11*(1+$P$18) -> 0
A12: Rent Increase (%) | D12: =(D11-C11)/D11 -> #DIV/0! | E12: =(E11-D11)/E11 -> #DIV/0! | F12: =(F11-E11)/F11 -> #DIV/0! | G12: =(G11-F11)/G11 -> #DIV/0! | H12: =(H11-G11)/H11 -> #DIV/0! | I12: =(I11-H11)/I11 -> #DIV/0! | J12: =(J11-I11)/J11 -> #DIV/0! | K12: =(K11-J11)/K11 -> #DIV/0! | ... M12: =(M11-L11)/M11 -> #DIV/0!
A14: Total Occupied Units | C14: =C4+C9 -> 8 | D14: =D4+D9 -> 8.8 | E14: =E4+E9 -> 9.6 | F14: =F4+F9 -> 10.4 | G14: =G4+G9 -> 11.2 | H14: =H4+H9 -> 12 | I14: =I4+I9 -> 12.8 | J14: =J4+J9 -> 13.6 | ... M14: =M4+M9 -> 16 | O14: =SUM(O4:O12) -> 9 | P14: =SUM(P4:P12) -> 17
A16: Revenue Head | B16: Actual | C16: Pro Forma | D16: Year 1 | E16: Year 2 | F16: Year 3 | G16: Year 4 | H16: Year 5 | I16: Year 6 | J16: Year 7 | K16: Year 8 | L16: Year 9 | M16: Year 10
A17: POH Rent | B17: 108000 | C17: =C6*C4*12 -> 21900 | D17: =C17*(1+$P17) -> 22338 | E17: =D17*(1+$P17) -> 22784.76 | F17: =E17*(1+$P17) -> 23240.455 | G17: =F17*(1+$P17) -> 23705.264 | H17: =G17*(1+$P17) -> 24179.37 | I17: =H17*(1+$P17) -> 24662.957 | J17: =I17*(1+$P17) -> 25156.216 | K17: =J17*(1+$P17) -> 25659.34 | ... M17: =L17*(1+$P17) -> 26695.978 | O17: =A17&"Increased by "&TEXT(P17,"0%")&" annually" -> POH Rent Increased by 2% annually | P17: 0.02
A18: RV Rent | B18: 0 | C18: =B18 -> 0 | D18: =D9*D11*12 -> 0 | E18: =E9*E11*12 -> 0 | F18: =F9*F11*12 -> 0 | G18: =G9*G11*12 -> 0 | H18: =H9*H11*12 -> 0 | I18: =I9*I11*12 -> 0 | J18: =J9*J11*12 -> 0 | K18: =K9*K11*12 -> 0 | ... M18: =M9*M11*12 -> 0 | O18: =A18&"Increased by "&TEXT(P18,"0%")&" annually" -> RV Rent Increased by 5% annually | P18: 0.05
A19: RTO Rent | C19: 88944 | D19: =RTO!G33 -> 88944 | E19: =RTO!H33 -> 90722.88 | F19: =RTO!I33 -> 92537.338 | G19: =RTO!J33 -> 94388.084 | H19: =RTO!K33 -> 96275.846 | I19: =RTO!L33 -> 0 | J19: =RTO!M33 -> 0 | K19: =RTO!N33 -> 0 | ... M19: =RTO!P33 -> 0
A20: Less: Vacancy Loss | C20: =-((($P$4-C4)*C6)+(($P$9-C9)*C11)) -> -2053.125 | D20: =-((($P$4-D4)*D6)+(($P$9-D9)*D11)) -> -1908.0375 | E20: =-((($P$4-E4)*E6)+(($P$9-E9)*E11)) -> -1756.3252 | F20: =-((($P$4-F4)*F6)+(($P$9-F9)*F11)) -> -1597.7813 | G20: =-((($P$4-G4)*G6)+(($P$9-G9)*G11)) -> -1432.1931 | H20: =-((($P$4-H4)*H6)+(($P$9-H9)*H11)) -> -1259.3422 | I20: =-((($P$4-I4)*I6)+(($P$9-I9)*I11)) -> -1079.0044 | J20: =-((($P$4-J4)*J6)+(($P$9-J9)*J11)) -> -890.94932 | ... M20: =-((($P$4-M4)*M6)+(($P$9-M9)*M11)) -> -278.0831
A21: Less: Non-Cash Rent | B21: 0 | C21: =B21 -> 0 | D21: 0 | E21: 0 | F21: 0 | G21: 0 | H21: 0 | I21: 0 | J21: 0 | K21: 0 | L21: 0 | M21: 0
A22: Less: Concessions | B22: 0 | C22: =B22 -> 0 | D22: 0 | E22: 0 | F22: 0 | G22: 0 | H22: 0 | I22: 0 | J22: 0 | K22: 0 | L22: 0 | M22: 0
A23: Less: Bad Debt | C23: =$P$23*(SUM(C17:C19)+C20+C21+C22) -> 2175.8175 | D23: =$P$23*(SUM(D17:D19)+D20+D21+D22) -> 2187.4792 | E23: =$P$23*(SUM(E17:E19)+E20+E21+E22) -> 2235.0263 | F23: =$P$23*(SUM(F17:F19)+F20+F21+F22) -> 2283.6002 | G23: =$P$23*(SUM(G17:G19)+G20+G21+G22) -> 2333.2231 | H23: =$P$23*(SUM(H17:H19)+H20+H21+H22) -> 2383.9175 | I23: =$P$23*(SUM(I17:I19)+I20+I21+I22) -> 471.67905 | J23: =$P$23*(SUM(J17:J19)+J20+J21+J22) -> 485.30534 | ... M23: =$P$23*(SUM(M17:M19)+M20+M21+M22) -> 528.35789 | O23: ="Assumed "&TEXT(P23,"0%") -> Assumed 2% | P23: 0.02
A24: Total Revenue | B24: =SUM(B17:B22) -> 108000 | C24: =SUM(C17:C22) -> 108790.88 | D24: =SUM(D17:D22) -> 109373.96 | E24: =SUM(E17:E22) -> 111751.31 | F24: =SUM(F17:F22) -> 114180.01 | G24: =SUM(G17:G22) -> 116661.16 | H24: =SUM(H17:H22) -> 119195.87 | I24: =SUM(I17:I22) -> 23583.953 | ... M24: =SUM(M17:M22) -> 26417.895
A26: Expense Head | B26: Actual | C26: Pro Forma | D26: Year 1 | E26: Year 2 | F26: Year 3 | G26: Year 4 | H26: Year 5 | I26: Year 6 | J26: Year 7 | K26: Year 8 | L26: Year 9 | M26: Year 10 | P26: Growth | Q26: Rate A | R26: Rate B / Count | S26: Est. Base Year
A27: POH R&M | B27: 0 | C27: =($Q$27*C14*12) -> 9600 | D27: =($Q$27*D14*12)*(1+$P$27) -> 10982.4 | E27: =($Q$27*E14*12)*(1+$P$27) -> 11980.8 | F27: =($Q$27*F14*12)*(1+$P$27) -> 12979.2 | G27: =($Q$27*G14*12)*(1+$P$27) -> 13977.6 | H27: =($Q$27*H14*12)*(1+$P$27) -> 14976 | I27: =($Q$27*I14*12)*(1+$P$27) -> 15974.4 | J27: =($Q$27*J14*12)*(1+$P$27) -> 16972.8 | K27: =($Q$27*K14*12)*(1+$P$27) -> 17971.2 | ... M27: =($Q$27*M14*12)*(1+$P$27) -> 19968 | O27: =IF(AND(B27=0,C27=0),"",IF(B27=C27,"Pro Forma Increased by "&TEXT($P27,"0%")&" annually","Assumed $"&TEXT(Q27,"0")&"/m/lot, "&"increased by "&TEXT($P27,"0%")&" annually")) -> Assumed $100/m/lot, increased by 4% annually | P27: 0.04 | Q27: 100
A28: POH Insurance | B28: 0 | C28: =($Q$28*C4*12) -> 14400 | D28: =($Q$28*D4*12)*(1+$P$28) -> 16473.6 | E28: =($Q$28*E4*12)*(1+$P$28) -> 17971.2 | F28: =($Q$28*F4*12)*(1+$P$28) -> 19468.8 | G28: =($Q$28*G4*12)*(1+$P$28) -> 20966.4 | H28: =($Q$28*H4*12)*(1+$P$28) -> 22464 | I28: =($Q$28*I4*12)*(1+$P$28) -> 23961.6 | J28: =($Q$28*J4*12)*(1+$P$28) -> 25459.2 | K28: =($Q$28*K4*12)*(1+$P$28) -> 26956.8 | ... M28: =($Q$28*M4*12)*(1+$P$28) -> 29952 | O28: =IF(AND(B28=0,C28=0),"",IF(C28=B28,"Pro Forma Increased by "&TEXT($P28,"0%")&" annually","Assumed $"&TEXT(Q28,"0")&"/m/lot, "&"increased by "&TEXT($P28,"0%")&" annually")) -> Assumed $150/m/lot, increased by 4% annually | P28: 0.04 | Q28: 150
A29: POH Expense | B29: 41200 | C29: =B29 -> 41200 | D29: =C29*(1+$P29) -> 42436 | E29: =D29*(1+$P29) -> 43709.08 | F29: =E29*(1+$P29) -> 45020.352 | G29: =F29*(1+$P29) -> 46370.963 | H29: =G29*(1+$P29) -> 47762.092 | I29: =H29*(1+$P29) -> 49194.955 | J29: =I29*(1+$P29) -> 50670.803 | K29: =J29*(1+$P29) -> 52190.927 | ... M29: =L29*(1+$P29) -> 55369.355 | O29: =IF(AND(B29=0,C29=0),"",IF(B29=C29,"Pro Forma Increased by "&TEXT($P29,"0%")&" annually","Assumed "&TEXT(Q49,"0%"))) -> Pro Forma Increased by 3% annually | P29: 0.03
A30: Other POH Expenses | B30: 0 | C30: =B30 -> 0 | D30: =B30*(1+$P30) -> 0 | E30: =D30*(1+$P30) -> 0 | F30: =E30*(1+$P30) -> 0 | G30: =F30*(1+$P30) -> 0 | H30: =G30*(1+$P30) -> 0 | I30: =H30*(1+$P30) -> 0 | J30: =I30*(1+$P30) -> 0 | K30: =J30*(1+$P30) -> 0 | L30: =K30*(1+$P30) -> 0 | M30: =L30*(1+$P30) -> 0 | O30: =IF(AND(B30=0,C30=0),"",IF(B30=C30,"Pro Forma Increased by "&TEXT($P30,"0%")&" annually","Assumed "&TEXT(Q50,"0%"))) | P30: 0.03 | S30: =Q30*R30*12 -> 0
A31: Total Expenses | B31: =SUM(B27:B30) -> 41200 | C31: =SUM(C27:C30) -> 65200 | D31: =SUM(D27:D30) -> 69892 | E31: =SUM(E27:E30) -> 73661.08 | F31: =SUM(F27:F30) -> 77468.352 | G31: =SUM(G27:G30) -> 81314.963 | H31: =SUM(H27:H30) -> 85202.092 | I31: =SUM(I27:I30) -> 89130.955 | ... M31: =SUM(M27:M30) -> 105289.35
A32: NOI | C32: =C24-C31 -> 43590.875 | D32: =D24-D31 -> 39481.962 | E32: =E24-E31 -> 38090.235 | F32: =F24-F31 -> 36711.659 | G32: =G24-G31 -> 35346.193 | H32: =H24-H31 -> 33993.782 | I32: =I24-I31 -> -65547.002 | J32: =J24-J31 -> -68837.536 | ... M32: =M24-M31 -> -78871.46
A33: Expense Ratio | C33: =C31/C24 -> 0.59931497 | D33: =D31/D24 -> 0.63901863 | E33: =E31/E24 -> 0.6591518 | F33: =F31/F24 -> 0.67847561 | G33: =G31/G24 -> 0.69701832 | H33: =H31/H24 -> 0.7148074 | I33: =I31/I24 -> 3.7793052 | J33: =J31/J24 -> 3.8368753 | ... M33: =M31/M24 -> 3.9855316

Sheet Cash Flow Model
A1: Acquisition Model - Consolidated (Land + POH)
A2: Land (Major) + POH (Minor) -> Total NOI. Price, debt terms and hold period come from the BOV sheet.
A4: Assumptions | D4: Deal Controls (from BOV sheet)
A5: Total Value = Purchase Price (from BOV) | B5: ='BOV '!B6 -> 1048462.1 | D5: Hold Period (Years) | E5: 10
A6: LTV (from BOV) | B6: ='BOV '!B19 -> 0.7 | D6: Purchase Price Used | E6: =B5 -> 1048462.1
A7: Interest Rate = SOFR + Spread (from BOV) | B7: ='BOV '!B21 -> 0.0687 | D7: Loan Amount | E7: =E6*B6 -> 733923.5
A8: Amort Years (from BOV) | B8: ='BOV '!B35 -> 30 | D8: Equity Invested | E8: =E6-E7 -> 314538.64
A9: Exit Cap | B9: 0.1
A10: Selling Costs % | B10: 0.02
A12: Line Item | B12: Proforma | C12: Year 1 | D12: Year 2 | E12: Year 3 | F12: Year 4 | G12: Year 5 | H12: Year 6 | I12: Year 7 | J12: Year 8 | K12: Year 9 | L12: Year 10
A13: Land Total Revenue | B13: =Land!C42 -> 153476.5 | C13: =Land!D42 -> 166194.49 | D13: =Land!E42 -> 178788.59 | E13: =Land!F42 -> 191964.83 | F13: =Land!G42 -> 205747.36 | G13: =Land!H42 -> 220161.26 | H13: =Land!I42 -> 235232.56 | I13: =Land!J42 -> 250988.3 | ... L13: =Land!M42 -> 283571.79
A14: POH Total Revenue | B14: ='POH '!C24 -> 108790.88 | C14: ='POH '!D24 -> 109373.96 | D14: ='POH '!E24 -> 111751.31 | E14: ='POH '!F24 -> 114180.01 | F14: ='POH '!G24 -> 116661.16 | G14: ='POH '!H24 -> 119195.87 | H14: ='POH '!I24 -> 23583.953 | I14: ='POH '!J24 -> 24265.267 | ... L14: ='POH '!M24 -> 26417.895
A15: Total Revenue | B15: =B13+B14 -> 262267.38 | C15: =C13+C14 -> 275568.45 | D15: =D13+D14 -> 290539.91 | E15: =E13+E14 -> 306144.85 | F15: =F13+F14 -> 322408.52 | G15: =G13+G14 -> 339357.13 | H15: =H13+H14 -> 258816.52 | I15: =I13+I14 -> 275253.57 | ... L15: =L13+L14 -> 309989.69
A16: Land Total Expenses | B16: =Land!C60 -> 80434.625 | C16: =Land!D60 -> 85499.247 | D16: =Land!E60 -> 89326.467 | E16: =Land!F60 -> 93217.984 | F16: =Land!G60 -> 97176.63 | G16: =Land!H60 -> 101205.36 | H16: =Land!I60 -> 105307.25 | I16: =Land!J60 -> 109485.53 | ... L16: =Land!M60 -> 116993.73
A17: POH Total Expenses | B17: ='POH '!C31 -> 65200 | C17: ='POH '!D31 -> 69892 | D17: ='POH '!E31 -> 73661.08 | E17: ='POH '!F31 -> 77468.352 | F17: ='POH '!G31 -> 81314.963 | G17: ='POH '!H31 -> 85202.092 | H17: ='POH '!I31 -> 89130.955 | I17: ='POH '!J31 -> 93102.803 | ... L17: ='POH '!M31 -> 105289.35
A18: Total Expenses | B18: =B16+B17 -> 145634.62 | C18: =C16+C17 -> 155391.25 | D18: =D16+D17 -> 162987.55 | E18: =E16+E17 -> 170686.34 | F18: =F16+F17 -> 178491.59 | G18: =G16+G17 -> 186407.45 | H18: =H16+H17 -> 194438.21 | I18: =I16+I17 -> 202588.33 | ... L18: =L16+L17 -> 222283.08
A19: NOI (Land + POH) | B19: =B15-B18 -> 116632.75 | C19: =C15-C18 -> 120177.2 | D19: =D15-D18 -> 127552.36 | E19: =E15-E18 -> 135458.51 | F19: =F15-F18 -> 143916.93 | G19: =G15-G18 -> 152949.68 | H19: =H15-H18 -> 64378.308 | I19: =I15-I18 -> 72665.238 | ... L19: =L15-L18 -> 87706.608
A20: Debt Service & Levered
A21: Debt Service (from Debt Sheet) | C21: ='Loan Amortization '!B12 -> 58373.774 | D21: ='Loan Amortization '!C12 -> 58373.774 | E21: ='Loan Amortization '!D12 -> 58373.774 | F21: ='Loan Amortization '!E12 -> 58373.774 | G21: ='Loan Amortization '!F12 -> 58373.774 | H21: ='Loan Amortization '!G12 -> 58373.774 | I21: ='Loan Amortization '!H12 -> 58373.774 | J21: ='Loan Amortization '!I12 -> 58373.774 | ... L21: ='Loan Amortization '!K12 -> 58373.774
A22: Interest | C22: ='Loan Amortization '!B13 -> 50420.545 | D22: ='Loan Amortization '!C13 -> 49874.158 | E22: ='Loan Amortization '!D13 -> 49290.234 | F22: ='Loan Amortization '!E13 -> 48666.195 | G22: ='Loan Amortization '!F13 -> 47999.284 | H22: ='Loan Amortization '!G13 -> 47286.557 | I22: ='Loan Amortization '!H13 -> 46524.865 | J22: ='Loan Amortization '!I13 -> 45710.845 | ... L22: ='Loan Amortization '!K13 -> 43911.194
A23: Principal | C23: ='Loan Amortization '!B14 -> 7953.229 | D23: ='Loan Amortization '!C14 -> 8499.6158 | E23: ='Loan Amortization '!D14 -> 9083.5395 | F23: ='Loan Amortization '!E14 -> 9707.5786 | G23: ='Loan Amortization '!F14 -> 10374.489 | H23: ='Loan Amortization '!G14 -> 11087.217 | I23: ='Loan Amortization '!H14 -> 11848.908 | J23: ='Loan Amortization '!I14 -> 12662.928 | ... L23: ='Loan Amortization '!K14 -> 14462.58
A24: Levered Cash Flow (NOI - Debt Service) | C24: =C19-C21 -> 61803.427 | D24: =D19-D21 -> 69178.587 | E24: =E19-E21 -> 77084.735 | F24: =F19-F21 -> 85543.152 | G24: =G19-G21 -> 94575.909 | H24: =H19-H21 -> 6004.5341 | I24: =I19-I21 -> 14291.464 | J24: =J19-J21 -> 23184.699 | ... L24: =L19-L21 -> 29332.835
A25: DSCR (NOI / Debt Service) | C25: =IF(C21=0,0,C19/C21) -> 2.0587533 | D25: =IF(D21=0,0,D19/D21) -> 2.1850971 | E25: =IF(E21=0,0,E19/E21) -> 2.3205371 | F25: =IF(F21=0,0,F19/F21) -> 2.4654381 | G25: =IF(G21=0,0,G19/G21) -> 2.6201781 | H25: =IF(H21=0,0,H19/H21) -> 1.1028636 | I25: =IF(I21=0,0,I19/I21) -> 1.2448268 | J25: =IF(J21=0,0,J19/J21) -> 1.3971766 | ... L25: =IF(L21=0,0,L19/L21) -> 1.5025002
A26: Expense Ratio | B26: =B18/B15 -> 0.55529066 | C26: =C18/C15 -> 0.56389347 | D26: =D18/D15 -> 0.56098162 | E26: =E18/E15 -> 0.55753458 | F26: =F18/F15 -> 0.55361934 | G26: =G18/G15 -> 0.54929581 | H26: =H18/H15 -> 0.75125889 | I26: =I18/I15 -> 0.7360062 | ... L26: =L18/L15 -> 0.71706605
A28: Exit & Appreciation (sale at end of hold period)
A29: Hold Period (Years) | B29: 10
A30: Exit-Year NOI (trailing) | B30: =INDEX(C19:L19,B29) -> 87706.608
A31: Exit Value (NOI / Exit Cap) | B31: =B30/B9 -> 877066.08
A32: Less: Selling Costs | B32: =B31*B10 -> 17541.322
A33: Less: Ending Loan Balance | B33: =INDEX('Loan Amortization '!B15:K15,B29) -> 624710.55
A34: Net Sale Proceeds | B34: =B31-B32-B33 -> 234814.22
A35: Appreciation (Exit Value - Purchase Price) | B35: =B31-E6 -> -171396.06
A37: Cash Flow to Equity & Returns
A38: Year | B38: 0 | C38: 1 | D38: 2 | E38: 3 | F38: 4 | G38: 5 | H38: 6 | I38: 7 | J38: 8 | K38: 9 | L38: 10
A39: Levered Cash Flow (incl. sale in hold year) | B39: =-E8 -> -314538.64 | C39: =IF(C$38<=$B$29,C24,0)+IF(C$38=$B$29,$B$34,0) -> 61803.427 | D39: =IF(D$38<=$B$29,D24,0)+IF(D$38=$B$29,$B$34,0) -> 69178.587 | E39: =IF(E$38<=$B$29,E24,0)+IF(E$38=$B$29,$B$34,0) -> 77084.735 | F39: =IF(F$38<=$B$29,F24,0)+IF(F$38=$B$29,$B$34,0) -> 85543.152 | G39: =IF(G$38<=$B$29,G24,0)+IF(G$38=$B$29,$B$34,0) -> 94575.909 | H39: =IF(H$38<=$B$29,H24,0)+IF(H$38=$B$29,$B$34,0) -> 6004.5341 | I39: =IF(I$38<=$B$29,I24,0)+IF(I$38=$B$29,$B$34,0) -> 14291.464 | J39: =IF(J$38<=$B$29,J24,0)+IF(J$38=$B$29,$B$34,0) -> 23184.699 | ... L39: =IF(L$38<=$B$29,L24,0)+IF(L$38=$B$29,$B$34,0) -> 264147.05
A40: Unlevered Cash Flow (incl. sale in hold year) | B40: =-E6 -> -1048462.1 | C40: =IF(C$38<=$B$29,C19,0)+IF(C$38=$B$29,$B$31-$B$32,0) -> 120177.2 | D40: =IF(D$38<=$B$29,D19,0)+IF(D$38=$B$29,$B$31-$B$32,0) -> 127552.36 | E40: =IF(E$38<=$B$29,E19,0)+IF(E$38=$B$29,$B$31-$B$32,0) -> 135458.51 | F40: =IF(F$38<=$B$29,F19,0)+IF(F$38=$B$29,$B$31-$B$32,0) -> 143916.93 | G40: =IF(G$38<=$B$29,G19,0)+IF(G$38=$B$29,$B$31-$B$32,0) -> 152949.68 | H40: =IF(H$38<=$B$29,H19,0)+IF(H$38=$B$29,$B$31-$B$32,0) -> 64378.308 | I40: =IF(I$38<=$B$29,I19,0)+IF(I$38=$B$29,$B$31-$B$32,0) -> 72665.238 | J40: =IF(J$38<=$B$29,J19,0)+IF(J$38=$B$29,$B$31-$B$32,0) -> 81558.472 | ... L40: =IF(L$38<=$B$29,L19,0)+IF(L$38=$B$29,$B$31-$B$32,0) -> 947231.37
A42: Levered IRR | B42: =IFERROR(IRR(B39:L39),IFERROR(IRR(B39:L39,-0.5),"n/a")) -> 0.17071022
A43: Unlevered IRR | B43: =IFERROR(IRR(B40:L40),IFERROR(IRR(B40:L40,-0.5),"n/a")) -> 0.095531206
A44: Equity Multiple | B44: =SUM(C39:L39)/E8 -> 2.2964913
A45: Cash-on-Cash (Year 1) | B45: =C24/E8 -> 0.19648914
...

Sheet IRR by Exit Year Analysis
A1: IRR - Returns by Exit Year
A2: Sale Year | B2: 1 | C2: 2 | D2: 3 | E2: 4 | F2: 5 | G2: 6 | H2: 7 | I2: 8 | J2: 9 | K2: 10
A3: Exit NOI (trailing) | B3: =INDEX('Cash Flow Model'!$C$19:$L$19,B$2) -> 120177.2 | C3: =INDEX('Cash Flow Model'!$C$19:$L$19,C$2) -> 127552.36 | D3: =INDEX('Cash Flow Model'!$C$19:$L$19,D$2) -> 135458.51 | E3: =INDEX('Cash Flow Model'!$C$19:$L$19,E$2) -> 143916.93 | F3: =INDEX('Cash Flow Model'!$C$19:$L$19,F$2) -> 152949.68 | G3: =INDEX('Cash Flow Model'!$C$19:$L$19,G$2) -> 64378.308 | H3: =INDEX('Cash Flow Model'!$C$19:$L$19,H$2) -> 72665.238 | I3: =INDEX('Cash Flow Model'!$C$19:$L$19,I$2) -> 81558.472 | ... K3: =INDEX('Cash Flow Model'!$C$19:$L$19,K$2) -> 87706.608
A4: Gross Exit Value | B4: =B3/'Cash Flow Model'!$B$9 -> 1201772 | C4: =C3/'Cash Flow Model'!$B$9 -> 1275523.6 | D4: =D3/'Cash Flow Model'!$B$9 -> 1354585.1 | E4: =E3/'Cash Flow Model'!$B$9 -> 1439169.3 | F4: =F3/'Cash Flow Model'!$B$9 -> 1529496.8 | G4: =G3/'Cash Flow Model'!$B$9 -> 643783.08 | H4: =H3/'Cash Flow Model'!$B$9 -> 726652.38 | I4: =I3/'Cash Flow Model'!$B$9 -> 815584.72 | ... K4: =K3/'Cash Flow Model'!$B$9 -> 877066.08
A5: Selling Costs | B5: =B4*'Cash Flow Model'!$B$10 -> 24035.44 | C5: =C4*'Cash Flow Model'!$B$10 -> 25510.472 | D5: =D4*'Cash Flow Model'!$B$10 -> 27091.702 | E5: =E4*'Cash Flow Model'!$B$10 -> 28783.385 | F5: =F4*'Cash Flow Model'!$B$10 -> 30589.937 | G5: =G4*'Cash Flow Model'!$B$10 -> 12875.662 | H5: =H4*'Cash Flow Model'!$B$10 -> 14533.048 | I5: =I4*'Cash Flow Model'!$B$10 -> 16311.694 | ... K5: =K4*'Cash Flow Model'!$B$10 -> 17541.322
A6: Ending Loan Balance | B6: =INDEX('Loan Amortization '!$B$15:$K$15,B$2) -> 725970.27 | C6: =INDEX('Loan Amortization '!$B$15:$K$15,C$2) -> 717470.66 | D6: =INDEX('Loan Amortization '!$B$15:$K$15,D$2) -> 708387.12 | E6: =INDEX('Loan Amortization '!$B$15:$K$15,E$2) -> 698679.54 | F6: =INDEX('Loan Amortization '!$B$15:$K$15,F$2) -> 688305.05 | G6: =INDEX('Loan Amortization '!$B$15:$K$15,G$2) -> 677217.83 | H6: =INDEX('Loan Amortization '!$B$15:$K$15,H$2) -> 665368.93 | I6: =INDEX('Loan Amortization '!$B$15:$K$15,I$2) -> 652706 | ... K6: =INDEX('Loan Amortization '!$B$15:$K$15,K$2) -> 624710.55
A7: Net Sale Proceeds | B7: =B4-B5-B6 -> 451766.29 | C7: =C4-C5-C6 -> 532542.48 | D7: =D4-D5-D6 -> 619106.27 | E7: =E4-E5-E6 -> 711706.33 | F7: =F4-F5-F6 -> 810601.84 | G7: =G4-G5-G6 -> -46310.418 | H7: =H4-H5-H6 -> 46750.404 | I7: =I4-I5-I6 -> 146567.03 | ... K7: =K4-K5-K6 -> 234814.22
A8: Levered Cash Flow in Sale Year | B8: =INDEX('Cash Flow Model'!$C$24:$L$24,B$2) -> 61803.427 | C8: =INDEX('Cash Flow Model'!$C$24:$L$24,C$2) -> 69178.587 | D8: =INDEX('Cash Flow Model'!$C$24:$L$24,D$2) -> 77084.735 | E8: =INDEX('Cash Flow Model'!$C$24:$L$24,E$2) -> 85543.152 | F8: =INDEX('Cash Flow Model'!$C$24:$L$24,F$2) -> 94575.909 | G8: =INDEX('Cash Flow Model'!$C$24:$L$24,G$2) -> 6004.5341 | H8: =INDEX('Cash Flow Model'!$C$24:$L$24,H$2) -> 14291.464 | I8: =INDEX('Cash Flow Model'!$C$24:$L$24,I$2) -> 23184.699 | ... K8: =INDEX('Cash Flow Model'!$C$24:$L$24,K$2) -> 29332.835
A9: Total Cash Flow in Sale Year | B9: =B7+B8 -> 513569.72 | C9: =C7+C8 -> 601721.06 | D9: =D7+D8 -> 696191.01 | E9: =E7+E8 -> 797249.49 | F9: =F7+F8 -> 905177.75 | G9: =G7+G8 -> -40305.884 | H9: =H7+H8 -> 61041.868 | I9: =I7+I8 -> 169751.73 | ... K9: =K7+K8 -> 264147.05
A10: Equity Invested | B10: ='Cash Flow Model'!$E$8 -> 314538.64 | C10: ='Cash Flow Model'!$E$8 -> 314538.64 | D10: ='Cash Flow Model'!$E$8 -> 314538.64 | E10: ='Cash Flow Model'!$E$8 -> 314538.64 | F10: ='Cash Flow Model'!$E$8 -> 314538.64 | G10: ='Cash Flow Model'!$E$8 -> 314538.64 | H10: ='Cash Flow Model'!$E$8 -> 314538.64 | I10: ='Cash Flow Model'!$E$8 -> 314538.64 | ... K10: ='Cash Flow Model'!$E$8 -> 314538.64
A11: Levered IRR | B11: =IFERROR(IRR($B17:$L17),IFERROR(IRR($B17:$L17,-0.5),"n/a")) -> 0.63277145 | C11: =IFERROR(IRR($B18:$L18),IFERROR(IRR($B18:$L18,-0.5),"n/a")) -> 0.48485174 | D11: =IFERROR(IRR($B19:$L19),IFERROR(IRR($B19:$L19,-0.5),"n/a")) -> 0.43102203 | E11: =IFERROR(IRR($B20:$L20),IFERROR(IRR($B20:$L20,-0.5),"n/a")) -> 0.40071442 | F11: =IFERROR(IRR($B21:$L21),IFERROR(IRR($B21:$L21,-0.5),"n/a")) -> 0.38039972 | G11: =IFERROR(IRR($B22:$L22),IFERROR(IRR($B22:$L22,-0.5),"n/a")) -> 0.035771041 | H11: =IFERROR(IRR($B23:$L23),IFERROR(IRR($B23:$L23,-0.5),"n/a")) -> 0.10869315 | I11: =IFERROR(IRR($B24:$L24),IFERROR(IRR($B24:$L24,-0.5),"n/a")) -> 0.15148094 | J11: =IFERROR(IRR($B25:$L25),IFERROR(IRR($B25:$L25,-0.5),"n/a")) -> 0.16355405 | K11: =IFERROR(IRR($B26:$L26),IFERROR(IRR($B26:$L26,-0.5),"n/a")) -> 0.17071022
A12: Equity Multiple | B12: =SUM($C17:$L17)/B10 -> 1.6327715 | C12: =SUM($C18:$L18)/C10 -> 2.1095166 | D12: =SUM($C19:$L19)/D10 -> 2.6297978 | E12: =SUM($C20:$L20)/E10 -> 3.1961613 | F12: =SUM($C21:$L21)/F10 -> 3.8112571 | G12: =SUM($C22:$L22)/G10 -> 1.1060006 | H12: =SUM($C23:$L23)/H10 -> 1.4473014 | I12: =SUM($C24:$L24)/I10 -> 1.8383545 | J12: =SUM($C25:$L25)/J10 -> 2.069668 | K12: =SUM($C26:$L26)/K10 -> 2.2964913
A13: Unlevered IRR | B13: =IFERROR(IRR($B30:$L30),IFERROR(IRR($B30:$L30,-0.5),"n/a")) -> 0.23792144 | C13: =IFERROR(IRR($B31:$L31),IFERROR(IRR($B31:$L31,-0.5),"n/a")) -> 0.20499409 | D13: =IFERROR(IRR($B32:$L32),IFERROR(IRR($B32:$L32,-0.5),"n/a")) -> 0.19446085 | E13: =IFERROR(IRR($B33:$L33),IFERROR(IRR($B33:$L33,-0.5),"n/a")) -> 0.18936535 | F13: =IFERROR(IRR($B34:$L34),IFERROR(IRR($B34:$L34,-0.5),"n/a")) -> 0.18639689 | G13: =IFERROR(IRR($B35:$L35),IFERROR(IRR($B35:$L35,-0.5),"n/a")) -> 0.062434557 | H13: =IFERROR(IRR($B36:$L36),IFERROR(IRR($B36:$L36,-0.5),"n/a")) -> 0.077464959 | I13: =IFERROR(IRR($B37:$L37),IFERROR(IRR($B37:$L37,-0.5),"n/a")) -> 0.089087645 | J13: =IFERROR(IRR($B38:$L38),IFERROR(IRR($B38:$L38,-0.5),"n/a")) -> 0.092913411 | K13: =IFERROR(IRR($B39:$L39),IFERROR(IRR($B39:$L39,-0.5),"n/a")) -> 0.095531206
A15: Levered cash flow to equity by exit year
A16: Exit Year / Period | B16: 0 | C16: 1 | D16: 2 | E16: 3 | F16: 4 | G16: 5 | H16: 6 | I16: 7 | J16: 8 | K16: 9 | L16: 10 | N16: IRR | O16: EM | P16: Profit
A17: 1 | B17: =-'Cash Flow Model'!$E$8 -> -314538.64 | C17: =IF(C$16<$A17,INDEX('Cash Flow Model'!$C$24:$L$24,C$16),IF(C$16=$A17,INDEX($B$9:$K$9,$A17),0)) -> 513569.72 | D17: =IF(D$16<$A17,INDEX('Cash Flow Model'!$C$24:$L$24,D$16),IF(D$16=$A17,INDEX($B$9:$K$9,$A17),0)) -> 0 | E17: =IF(E$16<$A17,INDEX('Cash Flow Model'!$C$24:$L$24,E$16),IF(E$16=$A17,INDEX($B$9:$K$9,$A17),0)) -> 0 | F17: =IF(F$16<$A17,INDEX('Cash Flow Model'!$C$24:$L$24,F$16),IF(F$16=$A17,INDEX($B$9:$K$9,$A17),0)) -> 0 | G17: =IF(G$16<$A17,INDEX('Cash Flow Model'!$C$24:$L$24,G$16),IF(G$16=$A17,INDEX($B$9:$K$9,$A17),0)) -> 0 | H17: =IF(H$16<$A17,INDEX('Cash Flow Model'!$C$24:$L$24,H$16),IF(H$16=$A17,INDEX($B$9:$K$9,$A17),0)) -> 0 | I17: =IF(I$16<$A17,INDEX('Cash Flow Model'!$C$24:$L$24,I$16),IF(I$16=$A17,INDEX($B$9:$K$9,$A17),0)) -> 0 | J17: =IF(J$16<$A17,INDEX('Cash Flow Model'!$C$24:$L$24,J$16),IF(J$16=$A17,INDEX($B$9:$K$9,$A17),0)) -> 0 | ... L17: =IF(L$16<$A17,INDEX('Cash Flow Model'!$C$24:$L$24,L$16),IF(L$16=$A17,INDEX($B$9:$K$9,$A17),0)) -> 0 | N17: =IFERROR(IRR(B17:L17),0) -> 0.63277145 | O17: =SUM(C17:L17)/'Cash Flow Model'!$E$8 -> 1.6327715 | P17: =SUM(C17:L17)-'Cash Flow Model'!$E$8 -> 199031.08
A18: 2 | B18: =-'Cash Flow Model'!$E$8 -> -314538.64 | C18: =IF(C$16<$A18,INDEX('Cash Flow Model'!$C$24:$L$24,C$16),IF(C$16=$A18,INDEX($B$9:$K$9,$A18),0)) -> 61803.427 | D18: =IF(D$16<$A18,INDEX('Cash Flow Model'!$C$24:$L$24,D$16),IF(D$16=$A18,INDEX($B$9:$K$9,$A18),0)) -> 601721.06 | E18: =IF(E$16<$A18,INDEX('Cash Flow Model'!$C$24:$L$24,E$16),IF(E$16=$A18,INDEX($B$9:$K$9,$A18),0)) -> 0 | F18: =IF(F$16<$A18,INDEX('Cash Flow Model'!$C$24:$L$24,F$16),IF(F$16=$A18,INDEX($B$9:$K$9,$A18),0)) -> 0 | G18: =IF(G$16<$A18,INDEX('Cash Flow Model'!$C$24:$L$24,G$16),IF(G$16=$A18,INDEX($B$9:$K$9,$A18),0)) -> 0 | H18: =IF(H$16<$A18,INDEX('Cash Flow Model'!$C$24:$L$24,H$16),IF(H$16=$A18,INDEX($B$9:$K$9,$A18),0)) -> 0 | I18: =IF(I$16<$A18,INDEX('Cash Flow Model'!$C$24:$L$24,I$16),IF(I$16=$A18,INDEX($B$9:$K$9,$A18),0)) -> 0 | J18: =IF(J$16<$A18,INDEX('Cash Flow Model'!$C$24:$L$24,J$16),IF(J$16=$A18,INDEX($B$9:$K$9,$A18),0)) -> 0 | ... L18: =IF(L$16<$A18,INDEX('Cash Flow Model'!$C$24:$L$24,L$16),IF(L$16=$A18,INDEX($B$9:$K$9,$A18),0)) -> 0 | N18: =IFERROR(IRR(B18:L18),0) -> 0.48485174 | O18: =SUM(C18:L18)/'Cash Flow Model'!$E$8 -> 2.1095166 | P18: =SUM(C18:L18)-'Cash Flow Model'!$E$8 -> 348985.85
A19: 3 | B19: =-'Cash Flow Model'!$E$8 -> -314538.64 | C19: =IF(C$16<$A19,INDEX('Cash Flow Model'!$C$24:$L$24,C$16),IF(C$16=$A19,INDEX($B$9:$K$9,$A19),0)) -> 61803.427 | D19: =IF(D$16<$A19,INDEX('Cash Flow Model'!$C$24:$L$24,D$16),IF(D$16=$A19,INDEX($B$9:$K$9,$A19),0)) -> 69178.587 | E19: =IF(E$16<$A19,INDEX('Cash Flow Model'!$C$24:$L$24,E$16),IF(E$16=$A19,INDEX($B$9:$K$9,$A19),0)) -> 696191.01 | F19: =IF(F$16<$A19,INDEX('Cash Flow Model'!$C$24:$L$24,F$16),IF(F$16=$A19,INDEX($B$9:$K$9,$A19),0)) -> 0 | G19: =IF(G$16<$A19,INDEX('Cash Flow Model'!$C$24:$L$24,G$16),IF(G$16=$A19,INDEX($B$9:$K$9,$A19),0)) -> 0 | H19: =IF(H$16<$A19,INDEX('Cash Flow Model'!$C$24:$L$24,H$16),IF(H$16=$A19,INDEX($B$9:$K$9,$A19),0)) -> 0 | I19: =IF(I$16<$A19,INDEX('Cash Flow Model'!$C$24:$L$24,I$16),IF(I$16=$A19,INDEX($B$9:$K$9,$A19),0)) -> 0 | J19: =IF(J$16<$A19,INDEX('Cash Flow Model'!$C$24:$L$24,J$16),IF(J$16=$A19,INDEX($B$9:$K$9,$A19),0)) -> 0 | ... L19: =IF(L$16<$A19,INDEX('Cash Flow Model'!$C$24:$L$24,L$16),IF(L$16=$A19,INDEX($B$9:$K$9,$A19),0)) -> 0 | N19: =IFERROR(IRR(B19:L19),0) -> 0.43102203 | O19: =SUM(C19:L19)/'Cash Flow Model'!$E$8 -> 2.6297978 | P19: =SUM(C19:L19)-'Cash Flow Model'!$E$8 -> 512634.38
A20: 4 | B20: =-'Cash Flow Model'!$E$8 -> -314538.64 | C20: =IF(C$16<$A20,INDEX('Cash Flow Model'!$C$24:$L$24,C$16),IF(C$16=$A20,INDEX($B$9:$K$9,$A20),0)) -> 61803.427 | D20: =IF(D$16<$A20,INDEX('Cash Flow Model'!$C$24:$L$24,D$16),IF(D$16=$A20,INDEX($B$9:$K$9,$A20),0)) -> 69178.587 | E20: =IF(E$16<$A20,INDEX('Cash Flow Model'!$C$24:$L$24,E$16),IF(E$16=$A20,INDEX($B$9:$K$9,$A20),0)) -> 77084.735 | F20: =IF(F$16<$A20,INDEX('Cash Flow Model'!$C$24:$L$24,F$16),IF(F$16=$A20,INDEX($B$9:$K$9,$A20),0)) -> 797249.49 | G20: =IF(G$16<$A20,INDEX('Cash Flow Model'!$C$24:$L$24,G$16),IF(G$16=$A20,INDEX($B$9:$K$9,$A20),0)) -> 0 | H20: =IF(H$16<$A20,INDEX('Cash Flow Model'!$C$24:$L$24,H$16),IF(H$16=$A20,INDEX($B$9:$K$9,$A20),0)) -> 0 | I20: =IF(I$16<$A20,INDEX('Cash Flow Model'!$C$24:$L$24,I$16),IF(I$16=$A20,INDEX($B$9:$K$9,$A20),0)) -> 0 | J20: =IF(J$16<$A20,INDEX('Cash Flow Model'!$C$24:$L$24,J$16),IF(J$16=$A20,INDEX($B$9:$K$9,$A20),0)) -> 0 | ... L20: =IF(L$16<$A20,INDEX('Cash Flow Model'!$C$24:$L$24,L$16),IF(L$16=$A20,INDEX($B$9:$K$9,$A20),0)) -> 0 | N20: =IFERROR(IRR(B20:L20),0) -> 0.40071442 | O20: =SUM(C20:L20)/'Cash Flow Model'!$E$8 -> 3.1961613 | P20: =SUM(C20:L20)-'Cash Flow Model'!$E$8 -> 690777.59
A21: 5 | B21: =-'Cash Flow Model'!$E$8 -> -314538.64 | C21: =IF(C$16<$A21,INDEX('Cash Flow Model'!$C$24:$L$24,C$16),IF(C$16=$A21,INDEX($B$9:$K$9,$A21),0)) -> 61803.427 | D21: =IF(D$16<$A21,INDEX('Cash Flow Model'!$C$24:$L$24,D$16),IF(D$16=$A21,INDEX($B$9:$K$9,$A21),0)) -> 69178.587 | E21: =IF(E$16<$A21,INDEX('Cash Flow Model'!$C$24:$L$24,E$16),IF(E$16=$A21,INDEX($B$9:$K$9,$A21),0)) -> 77084.735 | F21: =IF(F$16<$A21,INDEX('Cash Flow Model'!$C$24:$L$24,F$16),IF(F$16=$A21,INDEX($B$9:$K$9,$A21),0)) -> 85543.152 | G21: =IF(G$16<$A21,INDEX('Cash Flow Model'!$C$24:$L$24,G$16),IF(G$16=$A21,INDEX($B$9:$K$9,$A21),0)) -> 905177.75 | H21: =IF(H$16<$A21,INDEX('Cash Flow Model'!$C$24:$L$24,H$16),IF(H$16=$A21,INDEX($B$9:$K$9,$A21),0)) -> 0 | I21: =IF(I$16<$A21,INDEX('Cash Flow Model'!$C$24:$L$24,I$16),IF(I$16=$A21,INDEX($B$9:$K$9,$A21),0)) -> 0 | J21: =IF(J$16<$A21,INDEX('Cash Flow Model'!$C$24:$L$24,J$16),IF(J$16=$A21,INDEX($B$9:$K$9,$A21),0)) -> 0 | ... L21: =IF(L$16<$A21,INDEX('Cash Flow Model'!$C$24:$L$24,L$16),IF(L$16=$A21,INDEX($B$9:$K$9,$A21),0)) -> 0 | N21: =IFERROR(IRR(B21:L21),0) -> 0.38039972 | O21: =SUM(C21:L21)/'Cash Flow Model'!$E$8 -> 3.8112571 | P21: =SUM(C21:L21)-'Cash Flow Model'!$E$8 -> 884249.01
A22: 6 | B22: =-'Cash Flow Model'!$E$8 -> -314538.64 | C22: =IF(C$16<$A22,INDEX('Cash Flow Model'!$C$24:$L$24,C$16),IF(C$16=$A22,INDEX($B$9:$K$9,$A22),0)) -> 61803.427 | D22: =IF(D$16<$A22,INDEX('Cash Flow Model'!$C$24:$L$24,D$16),IF(D$16=$A22,INDEX($B$9:$K$9,$A22),0)) -> 69178.587 | E22: =IF(E$16<$A22,INDEX('Cash Flow Model'!$C$24:$L$24,E$16),IF(E$16=$A22,INDEX($B$9:$K$9,$A22),0)) -> 77084.735 | F22: =IF(F$16<$A22,INDEX('Cash Flow Model'!$C$24:$L$24,F$16),IF(F$16=$A22,INDEX($B$9:$K$9,$A22),0)) -> 85543.152 | G22: =IF(G$16<$A22,INDEX('Cash Flow Model'!$C$24:$L$24,G$16),IF(G$16=$A22,INDEX($B$9:$K$9,$A22),0)) -> 94575.909 | H22: =IF(H$16<$A22,INDEX('Cash Flow Model'!$C$24:$L$24,H$16),IF(H$16=$A22,INDEX($B$9:$K$9,$A22),0)) -> -40305.884 | I22: =IF(I$16<$A22,INDEX('Cash Flow Model'!$C$24:$L$24,I$16),IF(I$16=$A22,INDEX($B$9:$K$9,$A22),0)) -> 0 | J22: =IF(J$16<$A22,INDEX('Cash Flow Model'!$C$24:$L$24,J$16),IF(J$16=$A22,INDEX($B$9:$K$9,$A22),0)) -> 0 | ... L22: =IF(L$16<$A22,INDEX('Cash Flow Model'!$C$24:$L$24,L$16),IF(L$16=$A22,INDEX($B$9:$K$9,$A22),0)) -> 0 | N22: =IFERROR(IRR(B22:L22),0) -> 0.035771041 | O22: =SUM(C22:L22)/'Cash Flow Model'!$E$8 -> 1.1060006 | P22: =SUM(C22:L22)-'Cash Flow Model'!$E$8 -> 33341.283
A23: 7 | B23: =-'Cash Flow Model'!$E$8 -> -314538.64 | C23: =IF(C$16<$A23,INDEX('Cash Flow Model'!$C$24:$L$24,C$16),IF(C$16=$A23,INDEX($B$9:$K$9,$A23),0)) -> 61803.427 | D23: =IF(D$16<$A23,INDEX('Cash Flow Model'!$C$24:$L$24,D$16),IF(D$16=$A23,INDEX($B$9:$K$9,$A23),0)) -> 69178.587 | E23: =IF(E$16<$A23,INDEX('Cash Flow Model'!$C$24:$L$24,E$16),IF(E$16=$A23,INDEX($B$9:$K$9,$A23),0)) -> 77084.735 | F23: =IF(F$16<$A23,INDEX('Cash Flow Model'!$C$24:$L$24,F$16),IF(F$16=$A23,INDEX($B$9:$K$9,$A23),0)) -> 85543.152 | G23: =IF(G$16<$A23,INDEX('Cash Flow Model'!$C$24:$L$24,G$16),IF(G$16=$A23,INDEX($B$9:$K$9,$A23),0)) -> 94575.909 | H23: =IF(H$16<$A23,INDEX('Cash Flow Model'!$C$24:$L$24,H$16),IF(H$16=$A23,INDEX($B$9:$K$9,$A23),0)) -> 6004.5341 | I23: =IF(I$16<$A23,INDEX('Cash Flow Model'!$C$24:$L$24,I$16),IF(I$16=$A23,INDEX($B$9:$K$9,$A23),0)) -> 61041.868 | J23: =IF(J$16<$A23,INDEX('Cash Flow Model'!$C$24:$L$24,J$16),IF(J$16=$A23,INDEX($B$9:$K$9,$A23),0)) -> 0 | ... L23: =IF(L$16<$A23,INDEX('Cash Flow Model'!$C$24:$L$24,L$16),IF(L$16=$A23,INDEX($B$9:$K$9,$A23),0)) -> 0 | N23: =IFERROR(IRR(B23:L23),0) -> 0.10869315 | O23: =SUM(C23:L23)/'Cash Flow Model'!$E$8 -> 1.4473014 | P23: =SUM(C23:L23)-'Cash Flow Model'!$E$8 -> 140693.57
A24: 8 | B24: =-'Cash Flow Model'!$E$8 -> -314538.64 | C24: =IF(C$16<$A24,INDEX('Cash Flow Model'!$C$24:$L$24,C$16),IF(C$16=$A24,INDEX($B$9:$K$9,$A24),0)) -> 61803.427 | D24: =IF(D$16<$A24,INDEX('Cash Flow Model'!$C$24:$L$24,D$16),IF(D$16=$A24,INDEX($B$9:$K$9,$A24),0)) -> 69178.587 | E24: =IF(E$16<$A24,INDEX('Cash Flow Model'!$C$24:$L$24,E$16),IF(E$16=$A24,INDEX($B$9:$K$9,$A24),0)) -> 77084.735 | F24: =IF(F$16<$A24,INDEX('Cash Flow Model'!$C$24:$L$24,F$16),IF(F$16=$A24,INDEX($B$9:$K$9,$A24),0)) -> 85543.152 | G24: =IF(G$16<$A24,INDEX('Cash Flow Model'!$C$24:$L$24,G$16),IF(G$16=$A24,INDEX($B$9:$K$9,$A24),0)) -> 94575.909 | H24: =IF(H$16<$A24,INDEX('Cash Flow Model'!$C$24:$L$24,H$16),IF(H$16=$A24,INDEX($B$9:$K$9,$A24),0)) -> 6004.5341 | I24: =IF(I$16<$A24,INDEX('Cash Flow Model'!$C$24:$L$24,I$16),IF(I$16=$A24,INDEX($B$9:$K$9,$A24),0)) -> 14291.464 | J24: =IF(J$16<$A24,INDEX('Cash Flow Model'!$C$24:$L$24,J$16),IF(J$16=$A24,INDEX($B$9:$K$9,$A24),0)) -> 169751.73 | ... L24: =IF(L$16<$A24,INDEX('Cash Flow Model'!$C$24:$L$24,L$16),IF(L$16=$A24,INDEX($B$9:$K$9,$A24),0)) -> 0 | N24: =IFERROR(IRR(B24:L24),0) -> 0.15148094 | O24: =SUM(C24:L24)/'Cash Flow Model'!$E$8 -> 1.8383545 | P24: =SUM(C24:L24)-'Cash Flow Model'!$E$8 -> 263694.89
A25: 9 | B25: =-'Cash Flow Model'!$E$8 -> -314538.64 | C25: =IF(C$16<$A25,INDEX('Cash Flow Model'!$C$24:$L$24,C$16),IF(C$16=$A25,INDEX($B$9:$K$9,$A25),0)) -> 61803.427 | D25: =IF(D$16<$A25,INDEX('Cash Flow Model'!$C$24:$L$24,D$16),IF(D$16=$A25,INDEX($B$9:$K$9,$A25),0)) -> 69178.587 | E25: =IF(E$16<$A25,INDEX('Cash Flow Model'!$C$24:$L$24,E$16),IF(E$16=$A25,INDEX($B$9:$K$9,$A25),0)) -> 77084.735 | F25: =IF(F$16<$A25,INDEX('Cash Flow Model'!$C$24:$L$24,F$16),IF(F$16=$A25,INDEX($B$9:$K$9,$A25),0)) -> 85543.152 | G25: =IF(G$16<$A25,INDEX('Cash Flow Model'!$C$24:$L$24,G$16),IF(G$16=$A25,INDEX($B$9:$K$9,$A25),0)) -> 94575.909 | H25: =IF(H$16<$A25,INDEX('Cash Flow Model'!$C$24:$L$24,H$16),IF(H$16=$A25,INDEX($B$9:$K$9,$A25),0)) -> 6004.5341 | I25: =IF(I$16<$A25,INDEX('Cash Flow Model'!$C$24:$L$24,I$16),IF(I$16=$A25,INDEX($B$9:$K$9,$A25),0)) -> 14291.464 | J25: =IF(J$16<$A25,INDEX('Cash Flow Model'!$C$24:$L$24,J$16),IF(J$16=$A25,INDEX($B$9:$K$9,$A25),0)) -> 23184.699 | ... L25: =IF(L$16<$A25,INDEX('Cash Flow Model'!$C$24:$L$24,L$16),IF(L$16=$A25,INDEX($B$9:$K$9,$A25),0)) -> 0 | N25: =IFERROR(IRR(B25:L25),0) -> 0.16355405 | O25: =SUM(C25:L25)/'Cash Flow Model'!$E$8 -> 2.069668 | P25: =SUM(C25:L25)-'Cash Flow Model'!$E$8 -> 336451.93
A26: 10 | B26: =-'Cash Flow Model'!$E$8 -> -314538.64 | C26: =IF(C$16<$A26,INDEX('Cash Flow Model'!$C$24:$L$24,C$16),IF(C$16=$A26,INDEX($B$9:$K$9,$A26),0)) -> 61803.427 | D26: =IF(D$16<$A26,INDEX('Cash Flow Model'!$C$24:$L$24,D$16),IF(D$16=$A26,INDEX($B$9:$K$9,$A26),0)) -> 69178.587 | E26: =IF(E$16<$A26,INDEX('Cash Flow Model'!$C$24:$L$24,E$16),IF(E$16=$A26,INDEX($B$9:$K$9,$A26),0)) -> 77084.735 | F26: =IF(F$16<$A26,INDEX('Cash Flow Model'!$C$24:$L$24,F$16),IF(F$16=$A26,INDEX($B$9:$K$9,$A26),0)) -> 85543.152 | G26: =IF(G$16<$A26,INDEX('Cash Flow Model'!$C$24:$L$24,G$16),IF(G$16=$A26,INDEX($B$9:$K$9,$A26),0)) -> 94575.909 | H26: =IF(H$16<$A26,INDEX('Cash Flow Model'!$C$24:$L$24,H$16),IF(H$16=$A26,INDEX($B$9:$K$9,$A26),0)) -> 6004.5341 | I26: =IF(I$16<$A26,INDEX('Cash Flow Model'!$C$24:$L$24,I$16),IF(I$16=$A26,INDEX($B$9:$K$9,$A26),0)) -> 14291.464 | J26: =IF(J$16<$A26,INDEX('Cash Flow Model'!$C$24:$L$24,J$16),IF(J$16=$A26,INDEX($B$9:$K$9,$A26),0)) -> 23184.699 | ... L26: =IF(L$16<$A26,INDEX('Cash Flow Model'!$C$24:$L$24,L$16),IF(L$16=$A26,INDEX($B$9:$K$9,$A26),0)) -> 264147.05 | N26: =IFERROR(IRR(B26:L26),0) -> 0.17071022 | O26: =SUM(C26:L26)/'Cash Flow Model'!$E$8 -> 2.2964913 | P26: =SUM(C26:L26)-'Cash Flow Model'!$E$8 -> 407796.6
A28: Unlevered cash flow by exit year
A29: Exit Year / Period | B29: 0 | C29: 1 | D29: 2 | E29: 3 | F29: 4 | G29: 5 | H29: 6 | I29: 7 | J29: 8 | K29: 9 | L29: 10
A30: 1 | B30: =-'Cash Flow Model'!$E$6 -> -1048462.1 | C30: =IF(C$29<$A30,INDEX('Cash Flow Model'!$C$19:$L$19,C$29),IF(C$29=$A30,INDEX('Cash Flow Model'!$C$19:$L$19,C$29)+INDEX($B$4:$K$4,$A30)-INDEX($B$5:$K$5,$A30),0)) -> 1297913.8 | D30: =IF(D$29<$A30,INDEX('Cash Flow Model'!$C$19:$L$19,D$29),IF(D$29=$A30,INDEX('Cash Flow Model'!$C$19:$L$19,D$29)+INDEX($B$4:$K$4,$A30)-INDEX($B$5:$K$5,$A30),0)) -> 0 | E30: =IF(E$29<$A30,INDEX('Cash Flow Model'!$C$19:$L$19,E$29),IF(E$29=$A30,INDEX('Cash Flow Model'!$C$19:$L$19,E$29)+INDEX($B$4:$K$4,$A30)-INDEX($B$5:$K$5,$A30),0)) -> 0 | F30: =IF(F$29<$A30,INDEX('Cash Flow Model'!$C$19:$L$19,F$29),IF(F$29=$A30,INDEX('Cash Flow Model'!$C$19:$L$19,F$29)+INDEX($B$4:$K$4,$A30)-INDEX($B$5:$K$5,$A30),0)) -> 0 | G30: =IF(G$29<$A30,INDEX('Cash Flow Model'!$C$19:$L$19,G$29),IF(G$29=$A30,INDEX('Cash Flow Model'!$C$19:$L$19,G$29)+INDEX($B$4:$K$4,$A30)-INDEX($B$5:$K$5,$A30),0)) -> 0 | H30: =IF(H$29<$A30,INDEX('Cash Flow Model'!$C$19:$L$19,H$29),IF(H$29=$A30,INDEX('Cash Flow Model'!$C$19:$L$19,H$29)+INDEX($B$4:$K$4,$A30)-INDEX($B$5:$K$5,$A30),0)) -> 0 | I30: =IF(I$29<$A30,INDEX('Cash Flow Model'!$C$19:$L$19,I$29),IF(I$29=$A30,INDEX('Cash Flow Model'!$C$19:$L$19,I$29)+INDEX($B$4:$K$4,$A30)-INDEX($B$5:$K$5,$A30),0)) -> 0 | J30: =IF(J$29<$A30,INDEX('Cash Flow Model'!$C$19:$L$19,J$29),IF(J$29=$A30,INDEX('Cash Flow Model'!$C$19:$L$19,J$29)+INDEX($B$4:$K$4,$A30)-INDEX($B$5:$K$5,$A30),0)) -> 0 | ... L30: =IF(L$29<$A30,INDEX('Cash Flow Model'!$C$19:$L$19,L$29),IF(L$29=$A30,INDEX('Cash Flow Model'!$C$19:$L$19,L$29)+INDEX($B$4:$K$4,$A30)-INDEX($B$5:$K$5,$A30),0)) -> 0
A31: 2 | B31: =-'Cash Flow Model'!$E$6 -> -1048462.1 | C31: =IF(C$29<$A31,INDEX('Cash Flow Model'!$C$19:$L$19,C$29),IF(C$29=$A31,INDEX('Cash Flow Model'!$C$19:$L$19,C$29)+INDEX($B$4:$K$4,$A31)-INDEX($B$5:$K$5,$A31),0)) -> 120177.2 | D31: =IF(D$29<$A31,INDEX('Cash Flow Model'!$C$19:$L$19,D$29),IF(D$29=$A31,INDEX('Cash Flow Model'!$C$19:$L$19,D$29)+INDEX($B$4:$K$4,$A31)-INDEX($B$5:$K$5,$A31),0)) -> 1377565.5 | E31: =IF(E$29<$A31,INDEX('Cash Flow Model'!$C$19:$L$19,E$29),IF(E$29=$A31,INDEX('Cash Flow Model'!$C$19:$L$19,E$29)+INDEX($B$4:$K$4,$A31)-INDEX($B$5:$K$5,$A31),0)) -> 0 | F31: =IF(F$29<$A31,INDEX('Cash Flow Model'!$C$19:$L$19,F$29),IF(F$29=$A31,INDEX('Cash Flow Model'!$C$19:$L$19,F$29)+INDEX($B$4:$K$4,$A31)-INDEX($B$5:$K$5,$A31),0)) -> 0 | G31: =IF(G$29<$A31,INDEX('Cash Flow Model'!$C$19:$L$19,G$29),IF(G$29=$A31,INDEX('Cash Flow Model'!$C$19:$L$19,G$29)+INDEX($B$4:$K$4,$A31)-INDEX($B$5:$K$5,$A31),0)) -> 0 | H31: =IF(H$29<$A31,INDEX('Cash Flow Model'!$C$19:$L$19,H$29),IF(H$29=$A31,INDEX('Cash Flow Model'!$C$19:$L$19,H$29)+INDEX($B$4:$K$4,$A31)-INDEX($B$5:$K$5,$A31),0)) -> 0 | I31: =IF(I$29<$A31,INDEX('Cash Flow Model'!$C$19:$L$19,I$29),IF(I$29=$A31,INDEX('Cash Flow Model'!$C$19:$L$19,I$29)+INDEX($B$4:$K$4,$A31)-INDEX($B$5:$K$5,$A31),0)) -> 0 | J31: =IF(J$29<$A31,INDEX('Cash Flow Model'!$C$19:$L$19,J$29),IF(J$29=$A31,INDEX('Cash Flow Model'!$C$19:$L$19,J$29)+INDEX($B$4:$K$4,$A31)-INDEX($B$5:$K$5,$A31),0)) -> 0 | ... L31: =IF(L$29<$A31,INDEX('Cash Flow Model'!$C$19:$L$19,L$29),IF(L$29=$A31,INDEX('Cash Flow Model'!$C$19:$L$19,L$29)+INDEX($B$4:$K$4,$A31)-INDEX($B$5:$K$5,$A31),0)) -> 0
